DEBUG 2019-01-17 10:13:45,467: 	 Executing command: 'resubmit'
DEBUG 2019-01-17 10:13:45,467: 	 Found CRAB cache file /afs/cern.ch/user/q/qihuang/.crab3
ERROR 2019-01-17 10:13:45,468: 	 Error: crab_SEle16H1-v1 is not a valid CRAB project directory.
ERROR 2019-01-17 10:13:45,468: 	 Caught exception
Traceback (most recent call last):
  File "/cvmfs/cms.cern.ch/crab3/slc6_amd64_gcc493/cms/crabclient/3.3.1812/bin/crab", line 160, in <module>
    client()
  File "/cvmfs/cms.cern.ch/crab3/slc6_amd64_gcc493/cms/crabclient/3.3.1812/bin/crab", line 146, in __call__
    self.cmd = sub_cmd(self.logger, args[1:])
  File "/cvmfs/cms.cern.ch/crab3/slc6_amd64_gcc493/cms/crabclient/3.3.1812/lib/python2.7/site-packages/CRABClient/Commands/resubmit.py", line 28, in __init__
    SubCommand.__init__(self, logger, cmdargs)
  File "/cvmfs/cms.cern.ch/crab3/slc6_amd64_gcc493/cms/crabclient/3.3.1812/lib/python2.7/site-packages/CRABClient/Commands/SubCommand.py", line 262, in __init__
    self.validateOptions()
  File "/cvmfs/cms.cern.ch/crab3/slc6_amd64_gcc493/cms/crabclient/3.3.1812/lib/python2.7/site-packages/CRABClient/Commands/resubmit.py", line 276, in validateOptions
    SubCommand.validateOptions(self)
  File "/cvmfs/cms.cern.ch/crab3/slc6_amd64_gcc493/cms/crabclient/3.3.1812/lib/python2.7/site-packages/CRABClient/Commands/SubCommand.py", line 575, in validateOptions
    raise ConfigurationException(msg)
ConfigurationException: [91mError[0m: crab_SEle16H1-v1 is not a valid CRAB project directory.
